<?xml version="1.0"?>
<robot xmlns:xacro="http://www.ros.org/wiki/xacro" name="robot">

    <xacro:include filename="inertial_macros.xacro"/>


    <material name="white">
        <color rgba="1 1 1 1"/>
    </material>

    <material name="black">
        <color rgba="0 0 0 1"/>
    </material>

    <material name="grey">
        <color rgba="0.5 0.5 0.5 1"/>
    </material>

    <material name="red">
        <color rgba="1 0 0 1"/>
    </material>

    <!-- BASE LINK -->
    <link name="base_link">
    
    </link>

    <!-- sase gövde-->
    <joint name="sase_joint" type="fixed">
        <origin xyz="0 0 0.04"/>
        <parent link="base_link"/>
        <child link="sase"/>
    </joint>
    
    <link name="sase">
        <visual>
            <geometry>
                <box size="0.615 0.345 0.09"/> <!-- 61.5 cm uzunluk, 34.5 cm genişlik, 9 cm yükseklik -->
            </geometry>
            <material name="grey"/>
            <origin xyz="0 0 0.04"/>
        </visual>

        <collision>
            <geometry>
                <box size="0.615 0.345 0.09"/> <!-- 61.5 cm uzunluk, 34.5 cm genişlik, 9 cm yükseklik -->
            </geometry>
            <origin xyz="0 0 0.04"/>
        </collision>
        <xacro:inertial_box mass="0.5" x="0.615" y="0.345" z="0.09">
            <origin xyz="0 0 0.04" rpy = "0 0 0"/>
        </xacro:inertial_box>
    </link>

    <gazebo reference="sase">
        <material>Gazebo/Grey</material>
    </gazebo>


    <!-- Ön tekerlerin çubuğa bağlanması -->
    <joint name="on_teker_joints" type="fixed">
        <origin xyz="0.112 0 0.02"/>
        <parent link="sase"/>
        <child link="on_teker_cubugu"/>
    </joint>

    <link name="on_teker_cubugu">
        <visual>
            <geometry>
                <cylinder radius="0.01" length="0.49"/> <!-- Örnek değerler -->
            </geometry>
            <material name="black"/>
            <origin xyz="0.112 0 0.02" rpy="${pi/2} 0 0"/>
        </visual>
        <collision>
            <geometry>
                <cylinder radius="0.01" length="0.49"/> <!-- Örnek değerler -->
            </geometry>
            <origin xyz="0.112 0 0.02"  rpy="${pi/2} 0 0"/>
        </collision>
    </link>

    <gazebo reference="on_teker_cubugu">
        <material>Gazebo/Blue</material>
    </gazebo>

    <!-- arka tekerlerin çubuğa bağlanması -->
    <joint name="arka_teker_joints" type="fixed">
        <origin xyz="-0.112 0 0.02" />
        <parent link="sase"/>
        <child link="arka_teker_cubugu"/>
    </joint>

    <link name="arka_teker_cubugu">
        <visual>
            <geometry>
                <cylinder radius="0.01" length="0.49"/> <!-- Örnek değerler -->
            </geometry>
            <material name="black"/>
            <origin xyz="-0.112 0 0.02"  rpy="${pi/2} 0 0"/>
        </visual>
        <collision>
            <geometry>
                <cylinder radius="0.01" length="0.49"/> <!-- Örnek değerler -->
            </geometry>
            <origin xyz="-0.112 0 0.02"  rpy="${pi/2} 0 0"/>
        </collision>
    </link>


    <gazebo reference="arka_teker_cubugu">
        <material>Gazebo/Blue</material>
    </gazebo>
    
    <!--sag on teker-->
    <joint name="sag_on_teker_joint" type="continuous">
        <origin xyz="0.225 -0.228 0.0825" rpy="${pi/2} 0 0"/>
        <parent link="base_link"/>
        <child link="sag_on_teker"/>
        <axis xyz="0 0 -1"/>
    </joint>
    
    <link name="sag_on_teker">
        <visual>
            <geometry>
                <cylinder radius="0.0775" length="0.06"/> <!-- 15.5 cm çap, 6 cm yükseklik -->
            </geometry>
            <material name="black"/>
            
        </visual>

        <collision>
            <geometry>
                <cylinder radius="0.0775" length="0.06"/> <!-- 15.5 cm çap, 6 cm yükseklik -->
            </geometry>
           
        </collision>
        <xacro:inertial_cylinder mass="1" length="0.06" radius="0.0775"> <!-- 15.5 cm çap, 6 cm yükseklik -->
            <origin xyz="0.225 0.228 0.0825" rpy="${pi/2} 0 0"/>

        </xacro:inertial_cylinder>
    </link>

    <gazebo reference="sag_on_teker">
        <material>Gazebo/Black</material>
    </gazebo>


    <!--sag arka teker-->
    <joint name="sag_arka_teker_joint" type="continuous">
        <origin xyz="-0.225 -0.228 0.0825" rpy="${pi/2} 0 0"/>
        <parent link="base_link"/>
        <child link="sag_arka_teker"/>
        <axis xyz="0 0 -1"/>
    </joint>

    
    <link name="sag_arka_teker">
        <visual>
            <geometry>
                <cylinder radius="0.0775" length="0.06"/> <!-- 15.5 cm çap, 6 cm yükseklik -->
            </geometry>
            <material name="black"/>
           
        </visual>

        <collision>
            <geometry>
                <cylinder radius="0.0775" length="0.06"/> <!-- 15.5 cm çap, 6 cm yükseklik -->
            </geometry>
           
        </collision>
        <xacro:inertial_cylinder mass="1" length="0.06" radius="0.0775"> <!-- 15.5 cm çap, 6 cm yükseklik -->
        <origin xyz="-0.225 0.228 0.0825" rpy="-${pi/2} 0 0"/>
        </xacro:inertial_cylinder>
    </link>

    <gazebo reference="sag_arka_teker">
        <material>Gazebo/Black</material>
    </gazebo>

    <!--sol on teker-->
    <joint name="sol_on_teker_joint" type="continuous">
        <origin xyz="0.225 0.228 0.0825" rpy = "-${pi/2} 0 0"/>
        <parent link="base_link"/>
        <child link="sol_on_teker"/>
        <axis xyz="0 0 1"/>
    </joint>
    
    <link name="sol_on_teker">
        <visual>
            <geometry>
                <cylinder radius="0.0775" length="0.06"/> <!-- 15.5 cm çap, 6 cm yükseklik -->
            </geometry>
            <material name="black"/>
            
        </visual>

        <collision>
            <geometry>
                <cylinder radius="0.0775" length="0.06"/> <!-- 15.5 cm çap, 6 cm yükseklik -->
            </geometry>
            
        </collision>
        <xacro:inertial_cylinder mass="1" length="0.06" radius="0.0775"> <!-- 15.5 cm çap, 6 cm yükseklik -->
            <origin xyz="0.225 -0.228 0.0825" rpy = "${pi/2} 0 0"/>
        </xacro:inertial_cylinder>
    </link>

    <gazebo reference="sol_on_teker">
        <material>Gazebo/Black</material>
    </gazebo>

    <!--sol arka teker-->
    <joint name="sol_arka_teker_joint" type="continuous">
        <origin xyz="-0.225 0.228 0.0825" rpy="-${pi/2} 0 0"/>
        <parent link="base_link"/>
        <child link="sol_arka_teker"/>
        <axis xyz="0 0 1"/>
    </joint>
    
    <link name="sol_arka_teker">
        <visual>
            <geometry>
                <cylinder radius="0.0775" length="0.06"/> <!-- 15.5 cm çap, 6 cm yükseklik -->
            </geometry>
            <material name="black"/>
            
        </visual>

        <collision>
            <geometry>
                <cylinder radius="0.0775" length="0.06"/> <!-- 15.5 cm çap, 6 cm yükseklik -->
            </geometry>
            
        </collision>
        <xacro:inertial_cylinder mass="1" length="0.06" radius="0.0775"> <!-- 15.5 cm çap, 6 cm yükseklik -->
            <origin xyz="-0.225 -0.228 0.0825" rpy="-${pi/2} 0 0"/>
        </xacro:inertial_cylinder>
    </link>

    <gazebo reference="sol_arka_teker">
        <material>Gazebo/Black</material>
    </gazebo>

</robot>
