<sdf version='1.7'>
  <world name='default'>
    <light name='sun' type='directional'>
      <cast_shadows>1</cast_shadows>
      <pose>0 0 10 0 -0 0</pose>
      <diffuse>0.8 0.8 0.8 1</diffuse>
      <specular>0.2 0.2 0.2 1</specular>
      <attenuation>
        <range>1000</range>
        <constant>0.9</constant>
        <linear>0.01</linear>
        <quadratic>0.001</quadratic>
      </attenuation>
      <direction>-0.5 0.1 -0.9</direction>
      <spot>
        <inner_angle>0</inner_angle>
        <outer_angle>0</outer_angle>
        <falloff>0</falloff>
      </spot>
    </light>
    <model name='ground_plane'>
      <static>1</static>
      <link name='link'>
        <collision name='collision'>
          <geometry>
            <plane>
              <normal>0 0 1</normal>
              <size>100 100</size>
            </plane>
          </geometry>
          <surface>
            <contact>
              <collide_bitmask>65535</collide_bitmask>
              <ode/>
            </contact>
            <friction>
              <ode>
                <mu>100</mu>
                <mu2>50</mu2>
              </ode>
              <torsional>
                <ode/>
              </torsional>
            </friction>
            <bounce/>
          </surface>
          <max_contacts>10</max_contacts>
        </collision>
        <visual name='visual'>
          <cast_shadows>0</cast_shadows>
          <geometry>
            <plane>
              <normal>0 0 1</normal>
              <size>100 100</size>
            </plane>
          </geometry>
          <material>
            <script>
              <uri>file://media/materials/scripts/gazebo.material</uri>
              <name>Gazebo/Grey</name>
            </script>
          </material>
        </visual>
        <self_collide>0</self_collide>
        <enable_wind>0</enable_wind>
        <kinematic>0</kinematic>
      </link>
    </model>
    <gravity>0 0 -9.8</gravity>
    <magnetic_field>6e-06 2.3e-05 -4.2e-05</magnetic_field>
    <atmosphere type='adiabatic'/>
    <physics type='ode'>
      <max_step_size>0.001</max_step_size>
      <real_time_factor>1</real_time_factor>
      <real_time_update_rate>1000</real_time_update_rate>
    </physics>
    <scene>
      <ambient>0.4 0.4 0.4 1</ambient>
      <background>0.7 0.7 0.7 1</background>
      <shadows>1</shadows>
    </scene>
    <wind/>
    <spherical_coordinates>
      <surface_model>EARTH_WGS84</surface_model>
      <latitude_deg>0</latitude_deg>
      <longitude_deg>0</longitude_deg>
      <elevation>0</elevation>
      <heading_deg>0</heading_deg>
    </spherical_coordinates>
    <model name='my_bot'>
      <link name='base_link'>
        <inertial>
          <pose>0 0 0.08 0 -0 0</pose>
          <mass>1</mass>
          <inertia>
            <ixx>0.0105938</ixx>
            <ixy>0</ixy>
            <ixz>0</ixz>
            <iyy>0.0321937</iyy>
            <iyz>0</iyz>
            <izz>0.0414375</izz>
          </inertia>
        </inertial>
        <collision name='base_link_fixed_joint_lump__sase_collision'>
          <pose>0 0 0.08 0 -0 0</pose>
          <geometry>
            <box>
              <size>0.615 0.345 0.09</size>
            </box>
          </geometry>
          <surface>
            <contact>
              <ode/>
            </contact>
            <friction>
              <ode/>
              <torsional>
                <ode/>
              </torsional>
            </friction>
            <bounce/>
          </surface>
          <max_contacts>10</max_contacts>
        </collision>
        <collision name='base_link_fixed_joint_lump__arka_teker_cubugu_collision_1'>
          <pose>-0.224 0 0.08 1.5708 -0 0</pose>
          <geometry>
            <cylinder>
              <length>0.49</length>
              <radius>0.01</radius>
            </cylinder>
          </geometry>
          <surface>
            <contact>
              <ode/>
            </contact>
            <friction>
              <ode/>
              <torsional>
                <ode/>
              </torsional>
            </friction>
            <bounce/>
          </surface>
          <max_contacts>10</max_contacts>
        </collision>
        <collision name='base_link_fixed_joint_lump__on_teker_cubugu_collision_2'>
          <pose>0.224 0 0.08 1.5708 -0 0</pose>
          <geometry>
            <cylinder>
              <length>0.49</length>
              <radius>0.01</radius>
            </cylinder>
          </geometry>
          <surface>
            <contact>
              <ode/>
            </contact>
            <friction>
              <ode/>
              <torsional>
                <ode/>
              </torsional>
            </friction>
            <bounce/>
          </surface>
          <max_contacts>10</max_contacts>
        </collision>
        <visual name='base_link_fixed_joint_lump__sase_visual'>
          <pose>0 0 0.08 0 -0 0</pose>
          <geometry>
            <box>
              <size>0.615 0.345 0.09</size>
            </box>
          </geometry>
          <material>
            <script>
              <name>Gazebo/Grey</name>
              <uri>file://media/materials/scripts/gazebo.material</uri>
            </script>
          </material>
        </visual>
        <visual name='base_link_fixed_joint_lump__arka_teker_cubugu_visual_1'>
          <pose>-0.224 0 0.08 1.5708 -0 0</pose>
          <geometry>
            <cylinder>
              <length>0.49</length>
              <radius>0.01</radius>
            </cylinder>
          </geometry>
          <material>
            <script>
              <name>Gazebo/Blue</name>
              <uri>file://media/materials/scripts/gazebo.material</uri>
            </script>
          </material>
        </visual>
        <visual name='base_link_fixed_joint_lump__on_teker_cubugu_visual_2'>
          <pose>0.224 0 0.08 1.5708 -0 0</pose>
          <geometry>
            <cylinder>
              <length>0.49</length>
              <radius>0.01</radius>
            </cylinder>
          </geometry>
          <material>
            <script>
              <name>Gazebo/Blue</name>
              <uri>file://media/materials/scripts/gazebo.material</uri>
            </script>
          </material>
        </visual>
        <self_collide>0</self_collide>
        <enable_wind>0</enable_wind>
        <kinematic>0</kinematic>
      </link>
      <joint name='sag_arka_teker_joint' type='revolute'>
        <pose relative_to='base_link'>-0.225 0.228 0.0825 -1.5708 0 0</pose>
        <parent>base_link</parent>
        <child>sag_arka_teker</child>
        <axis>
          <xyz>0 0 -1</xyz>
          <limit>
            <lower>-1e+16</lower>
            <upper>1e+16</upper>
          </limit>
          <dynamics>
            <spring_reference>0</spring_reference>
            <spring_stiffness>0</spring_stiffness>
          </dynamics>
        </axis>
      </joint>
      <link name='sag_arka_teker'>
        <pose relative_to='sag_arka_teker_joint'>0 0 0 0 -0 0</pose>
        <inertial>
          <pose>-0.225 0.228 0.0825 -1.5708 0 0</pose>
          <mass>0.5</mass>
          <inertia>
            <ixx>0.000900781</ixx>
            <ixy>0</ixy>
            <ixz>0</ixz>
            <iyy>0.000900781</iyy>
            <iyz>0</iyz>
            <izz>0.00150156</izz>
          </inertia>
        </inertial>
        <collision name='sag_arka_teker_collision'>
          <pose>0 0 0 0 -0 0</pose>
          <geometry>
            <cylinder>
              <length>0.06</length>
              <radius>0.0775</radius>
            </cylinder>
          </geometry>
          <surface>
            <contact>
              <ode/>
            </contact>
            <friction>
              <ode/>
              <torsional>
                <ode/>
              </torsional>
            </friction>
            <bounce/>
          </surface>
          <max_contacts>10</max_contacts>
        </collision>
        <visual name='sag_arka_teker_visual'>
          <pose>0 0 0 0 -0 0</pose>
          <geometry>
            <cylinder>
              <length>0.06</length>
              <radius>0.0775</radius>
            </cylinder>
          </geometry>
          <material>
            <script>
              <name>Gazebo/Black</name>
              <uri>file://media/materials/scripts/gazebo.material</uri>
            </script>
          </material>
        </visual>
        <self_collide>0</self_collide>
        <enable_wind>0</enable_wind>
        <kinematic>0</kinematic>
      </link>
      <joint name='sag_on_teker_joint' type='revolute'>
        <pose relative_to='base_link'>0.225 0.228 0.0825 -1.5708 0 0</pose>
        <parent>base_link</parent>
        <child>sag_on_teker</child>
        <axis>
          <xyz>0 0 -1</xyz>
          <limit>
            <lower>-1e+16</lower>
            <upper>1e+16</upper>
          </limit>
          <dynamics>
            <spring_reference>0</spring_reference>
            <spring_stiffness>0</spring_stiffness>
          </dynamics>
        </axis>
      </joint>
      <link name='sag_on_teker'>
        <pose relative_to='sag_on_teker_joint'>0 0 0 0 -0 0</pose>
        <inertial>
          <pose>0.225 0.228 0.0825 1.5708 -0 0</pose>
          <mass>0.5</mass>
          <inertia>
            <ixx>0.000900781</ixx>
            <ixy>0</ixy>
            <ixz>0</ixz>
            <iyy>0.000900781</iyy>
            <iyz>0</iyz>
            <izz>0.00150156</izz>
          </inertia>
        </inertial>
        <collision name='sag_on_teker_collision'>
          <pose>0 0 0 0 -0 0</pose>
          <geometry>
            <cylinder>
              <length>0.06</length>
              <radius>0.0775</radius>
            </cylinder>
          </geometry>
          <surface>
            <contact>
              <ode/>
            </contact>
            <friction>
              <ode/>
              <torsional>
                <ode/>
              </torsional>
            </friction>
            <bounce/>
          </surface>
          <max_contacts>10</max_contacts>
        </collision>
        <visual name='sag_on_teker_visual'>
          <pose>0 0 0 0 -0 0</pose>
          <geometry>
            <cylinder>
              <length>0.06</length>
              <radius>0.0775</radius>
            </cylinder>
          </geometry>
          <material>
            <script>
              <name>Gazebo/Black</name>
              <uri>file://media/materials/scripts/gazebo.material</uri>
            </script>
          </material>
        </visual>
        <self_collide>0</self_collide>
        <enable_wind>0</enable_wind>
        <kinematic>0</kinematic>
      </link>
      <joint name='sol_arka_teker_joint' type='revolute'>
        <pose relative_to='base_link'>-0.225 -0.228 0.0825 1.5708 -0 0</pose>
        <parent>base_link</parent>
        <child>sol_arka_teker</child>
        <axis>
          <xyz>0 0 1</xyz>
          <limit>
            <lower>-1e+16</lower>
            <upper>1e+16</upper>
          </limit>
          <dynamics>
            <spring_reference>0</spring_reference>
            <spring_stiffness>0</spring_stiffness>
          </dynamics>
        </axis>
      </joint>
      <link name='sol_arka_teker'>
        <pose relative_to='sol_arka_teker_joint'>0 0 0 0 -0 0</pose>
        <inertial>
          <pose>-0.225 -0.228 0.0825 -1.5708 0 0</pose>
          <mass>0.5</mass>
          <inertia>
            <ixx>0.000900781</ixx>
            <ixy>0</ixy>
            <ixz>0</ixz>
            <iyy>0.000900781</iyy>
            <iyz>0</iyz>
            <izz>0.00150156</izz>
          </inertia>
        </inertial>
        <collision name='sol_arka_teker_collision'>
          <pose>0 0 0 0 -0 0</pose>
          <geometry>
            <cylinder>
              <length>0.06</length>
              <radius>0.0775</radius>
            </cylinder>
          </geometry>
          <surface>
            <contact>
              <ode/>
            </contact>
            <friction>
              <ode/>
              <torsional>
                <ode/>
              </torsional>
            </friction>
            <bounce/>
          </surface>
          <max_contacts>10</max_contacts>
        </collision>
        <visual name='sol_arka_teker_visual'>
          <pose>0 0 0 0 -0 0</pose>
          <geometry>
            <cylinder>
              <length>0.06</length>
              <radius>0.0775</radius>
            </cylinder>
          </geometry>
          <material>
            <script>
              <name>Gazebo/Black</name>
              <uri>file://media/materials/scripts/gazebo.material</uri>
            </script>
          </material>
        </visual>
        <self_collide>0</self_collide>
        <enable_wind>0</enable_wind>
        <kinematic>0</kinematic>
      </link>
      <joint name='sol_on_teker_joint' type='revolute'>
        <pose relative_to='base_link'>0.225 -0.228 0.0825 1.5708 -0 0</pose>
        <parent>base_link</parent>
        <child>sol_on_teker</child>
        <axis>
          <xyz>0 0 1</xyz>
          <limit>
            <lower>-1e+16</lower>
            <upper>1e+16</upper>
          </limit>
          <dynamics>
            <spring_reference>0</spring_reference>
            <spring_stiffness>0</spring_stiffness>
          </dynamics>
        </axis>
      </joint>
      <link name='sol_on_teker'>
        <pose relative_to='sol_on_teker_joint'>0 0 0 0 -0 0</pose>
        <inertial>
          <pose>0.225 -0.228 0.0825 1.5708 -0 0</pose>
          <mass>0.5</mass>
          <inertia>
            <ixx>0.000900781</ixx>
            <ixy>0</ixy>
            <ixz>0</ixz>
            <iyy>0.000900781</iyy>
            <iyz>0</iyz>
            <izz>0.00150156</izz>
          </inertia>
        </inertial>
        <collision name='sol_on_teker_collision'>
          <pose>0 0 0 0 -0 0</pose>
          <geometry>
            <cylinder>
              <length>0.06</length>
              <radius>0.0775</radius>
            </cylinder>
          </geometry>
          <surface>
            <contact>
              <ode/>
            </contact>
            <friction>
              <ode/>
              <torsional>
                <ode/>
              </torsional>
            </friction>
            <bounce/>
          </surface>
          <max_contacts>10</max_contacts>
        </collision>
        <visual name='sol_on_teker_visual'>
          <pose>0 0 0 0 -0 0</pose>
          <geometry>
            <cylinder>
              <length>0.06</length>
              <radius>0.0775</radius>
            </cylinder>
          </geometry>
          <material>
            <script>
              <name>Gazebo/Black</name>
              <uri>file://media/materials/scripts/gazebo.material</uri>
            </script>
          </material>
        </visual>
        <self_collide>0</self_collide>
        <enable_wind>0</enable_wind>
        <kinematic>0</kinematic>
      </link>
      <plugin name='front_wheel' filename='libgazebo_ros_diff_drive.so'>
        <left_joint>sol_on_teker_joint</left_joint>
        <right_joint>sag_on_teker_joint</right_joint>
        <wheel_separation>0.44</wheel_separation>
        <wheel_diameter>0.33</wheel_diameter>
        <max_wheel_torque>5</max_wheel_torque>
        <max_wheel_acceleration>5</max_wheel_acceleration>
        <odometry_frame>odom</odometry_frame>
        <robot_base_frame>base_link</robot_base_frame>
        <publish_odom>1</publish_odom>
        <publish_odom_tf>1</publish_odom_tf>
        <publish_wheel_tf>1</publish_wheel_tf>
      </plugin>
      <static>0</static>
      <plugin name='rear_wheel' filename='libgazebo_ros_diff_drive.so'>
        <left_joint>sol_arka_teker_joint</left_joint>
        <right_joint>sag_arka_teker_joint</right_joint>
        <wheel_separation>0.44</wheel_separation>
        <wheel_diameter>0.33</wheel_diameter>
        <max_wheel_torque>5</max_wheel_torque>
        <max_wheel_acceleration>5</max_wheel_acceleration>
        <odometry_frame>odom</odometry_frame>
        <robot_base_frame>base_link</robot_base_frame>
        <publish_odom>1</publish_odom>
        <publish_odom_tf>1</publish_odom_tf>
        <publish_wheel_tf>1</publish_wheel_tf>
      </plugin>
      <pose>0 0 0 0 -0 0</pose>
    </model>
    <model name='cabinet'>
      <static>1</static>
      <link name='cabinet_bottom_plate'>
        <inertial>
          <pose>0 0 -1 0 -0 0</pose>
          <inertia>
            <ixx>2.05</ixx>
            <ixy>0</ixy>
            <ixz>0</ixz>
            <iyy>2.05</iyy>
            <iyz>0</iyz>
            <izz>2.05</izz>
          </inertia>
          <mass>25</mass>
        </inertial>
        <collision name='cabinet_bottom_plate_geom'>
          <pose>0 0 0.01 0 -0 0</pose>
          <geometry>
            <box>
              <size>0.45 0.45 0.02</size>
            </box>
          </geometry>
          <max_contacts>10</max_contacts>
          <surface>
            <contact>
              <ode/>
            </contact>
            <bounce/>
            <friction>
              <torsional>
                <ode/>
              </torsional>
              <ode/>
            </friction>
          </surface>
        </collision>
        <visual name='cabinet_bottom_plate_geom_visual'>
          <pose>0 0 0.01 0 -0 0</pose>
          <geometry>
            <box>
              <size>0.45 0.45 0.02</size>
            </box>
          </geometry>
          <material>
            <script>
              <uri>file://media/materials/scripts/gazebo.material</uri>
              <name>Gazebo/Wood</name>
            </script>
          </material>
        </visual>
        <collision name='cabinet_bottom_plate_geom_cabinet_back_plate'>
          <pose>0.235 0 0.51 0 -0 0</pose>
          <geometry>
            <box>
              <size>0.02 0.45 1.02</size>
            </box>
          </geometry>
          <max_contacts>10</max_contacts>
          <surface>
            <contact>
              <ode/>
            </contact>
            <bounce/>
            <friction>
              <torsional>
                <ode/>
              </torsional>
              <ode/>
            </friction>
          </surface>
        </collision>
        <visual name='cabinet_bottom_plate_geom_cabinet_back_plate_visual'>
          <pose>0.235 0 0.51 0 -0 0</pose>
          <geometry>
            <box>
              <size>0.02 0.45 1.02</size>
            </box>
          </geometry>
          <material>
            <script>
              <uri>file://media/materials/scripts/gazebo.material</uri>
              <name>Gazebo/Wood</name>
            </script>
          </material>
        </visual>
        <collision name='cabinet_bottom_plate_geom_cabinet_left_plate'>
          <pose>0 0.235 0.51 0 -0 0</pose>
          <geometry>
            <box>
              <size>0.45 0.02 1.02</size>
            </box>
          </geometry>
          <max_contacts>10</max_contacts>
          <surface>
            <contact>
              <ode/>
            </contact>
            <bounce/>
            <friction>
              <torsional>
                <ode/>
              </torsional>
              <ode/>
            </friction>
          </surface>
        </collision>
        <visual name='cabinet_bottom_plate_geom_cabinet_left_plate_visual'>
          <pose>0 0.235 0.51 0 -0 0</pose>
          <geometry>
            <box>
              <size>0.45 0.02 1.02</size>
            </box>
          </geometry>
          <material>
            <script>
              <uri>file://media/materials/scripts/gazebo.material</uri>
              <name>Gazebo/Wood</name>
            </script>
          </material>
        </visual>
        <collision name='cabinet_bottom_plate_geom_cabinet_middle_plate'>
          <pose>0 0 0.51 0 -0 0</pose>
          <geometry>
            <box>
              <size>0.45 0.45 0.02</size>
            </box>
          </geometry>
          <max_contacts>10</max_contacts>
          <surface>
            <contact>
              <ode/>
            </contact>
            <bounce/>
            <friction>
              <torsional>
                <ode/>
              </torsional>
              <ode/>
            </friction>
          </surface>
        </collision>
        <visual name='cabinet_bottom_plate_geom_cabinet_middle_plate_visual'>
          <pose>0 0 0.51 0 -0 0</pose>
          <geometry>
            <box>
              <size>0.45 0.45 0.02</size>
            </box>
          </geometry>
          <material>
            <script>
              <uri>file://media/materials/scripts/gazebo.material</uri>
              <name>Gazebo/Wood</name>
            </script>
          </material>
        </visual>
        <collision name='cabinet_bottom_plate_geom_cabinet_right_plate'>
          <pose>0 -0.235 0.51 0 -0 0</pose>
          <geometry>
            <box>
              <size>0.45 0.02 1.02</size>
            </box>
          </geometry>
          <max_contacts>10</max_contacts>
          <surface>
            <contact>
              <ode/>
            </contact>
            <bounce/>
            <friction>
              <torsional>
                <ode/>
              </torsional>
              <ode/>
            </friction>
          </surface>
        </collision>
        <visual name='cabinet_bottom_plate_geom_cabinet_right_plate_visual'>
          <pose>0 -0.235 0.51 0 -0 0</pose>
          <geometry>
            <box>
              <size>0.45 0.02 1.02</size>
            </box>
          </geometry>
          <material>
            <script>
              <uri>file://media/materials/scripts/gazebo.material</uri>
              <name>Gazebo/Wood</name>
            </script>
          </material>
        </visual>
        <collision name='cabinet_bottom_plate_geom_cabinet_top_plate'>
          <pose>0 0 1.01 0 -0 0</pose>
          <geometry>
            <box>
              <size>0.45 0.45 0.02</size>
            </box>
          </geometry>
          <max_contacts>10</max_contacts>
          <surface>
            <contact>
              <ode/>
            </contact>
            <bounce/>
            <friction>
              <torsional>
                <ode/>
              </torsional>
              <ode/>
            </friction>
          </surface>
        </collision>
        <visual name='cabinet_bottom_plate_geom_cabinet_top_plate_visual'>
          <pose>0 0 1.01 0 -0 0</pose>
          <geometry>
            <box>
              <size>0.45 0.45 0.02</size>
            </box>
          </geometry>
          <material>
            <script>
              <uri>file://media/materials/scripts/gazebo.material</uri>
              <name>Gazebo/Wood</name>
            </script>
          </material>
        </visual>
        <self_collide>0</self_collide>
        <enable_wind>0</enable_wind>
        <kinematic>0</kinematic>
      </link>
      <pose>-0.642695 1.96711 0 0 -0 0</pose>
    </model>
    <model name='bus'>
      <static>1</static>
      <link name='link'>
        <collision name='collision'>
          <geometry>
            <mesh>
              <scale>0.01 0.01 0.01</scale>
              <uri>model://bus/meshes/bus.obj</uri>
            </mesh>
          </geometry>
          <max_contacts>10</max_contacts>
          <surface>
            <contact>
              <ode/>
            </contact>
            <bounce/>
            <friction>
              <torsional>
                <ode/>
              </torsional>
              <ode/>
            </friction>
          </surface>
        </collision>
        <visual name='visual'>
          <geometry>
            <mesh>
              <scale>0.01 0.01 0.01</scale>
              <uri>model://bus/meshes/bus.obj</uri>
            </mesh>
          </geometry>
        </visual>
        <self_collide>0</self_collide>
        <enable_wind>0</enable_wind>
        <kinematic>0</kinematic>
      </link>
      <pose>-5.20051 1.80474 0 0 -0 0</pose>
    </model>
    <state world_name='default'>
      <sim_time>804 255000000</sim_time>
      <real_time>898 979321352</real_time>
      <wall_time>1711198569 716907373</wall_time>
      <iterations>804255</iterations>
      <model name='bus'>
        <pose>-5.20051 1.80474 0 0 -0 0</pose>
        <scale>1 1 1</scale>
        <link name='link'>
          <pose>-5.20051 1.80474 0 0 -0 0</pose>
          <velocity>0 0 0 0 -0 0</velocity>
          <acceleration>0 0 0 0 -0 0</acceleration>
          <wrench>0 0 0 0 -0 0</wrench>
        </link>
      </model>
      <model name='cabinet'>
        <pose>-0.642695 1.96711 0 0 -0 0</pose>
        <scale>1 1 1</scale>
        <link name='cabinet_bottom_plate'>
          <pose>-0.642695 1.96711 0 0 -0 0</pose>
          <velocity>0 0 0 0 -0 0</velocity>
          <acceleration>0 0 0 0 -0 0</acceleration>
          <wrench>0 0 0 0 -0 0</wrench>
        </link>
      </model>
      <model name='ground_plane'>
        <pose>0 0 0 0 -0 0</pose>
        <scale>1 1 1</scale>
        <link name='link'>
          <pose>0 0 0 0 -0 0</pose>
          <velocity>0 0 0 0 -0 0</velocity>
          <acceleration>0 0 0 0 -0 0</acceleration>
          <wrench>0 0 0 0 -0 0</wrench>
        </link>
      </model>
      <model name='my_bot'>
        <pose>-0.095385 0.155174 -0.005001 5e-06 1e-06 1.56013</pose>
        <scale>1 1 1</scale>
        <link name='base_link'>
          <pose>-0.095385 0.155174 -0.005001 5e-06 1e-06 1.56013</pose>
          <velocity>0.000836 -2.5e-05 1.2e-05 0.000181 0.012082 2.1e-05</velocity>
          <acceleration>3.6129 -0.061015 0.0245 -2.49686 -1.17005 -3.08339</acceleration>
          <wrench>3.6129 -0.061015 0.0245 0 -0 0</wrench>
        </link>
        <link name='sag_arka_teker'>
          <pose>-0.325776 -0.067382 0.077502 -1.57083 -0.797574 1.56015</pose>
          <velocity>0.000554 7e-06 0.003111 -1.2e-05 0.007123 -0.001397</velocity>
          <acceleration>-3.42402 0.247007 7.39512 -0.088714 -0.523412 2.51332</acceleration>
          <wrench>-1.71201 0.123503 3.69756 0 -0 0</wrench>
        </link>
        <link name='sag_on_teker'>
          <pose>-0.320976 0.382593 0.077502 -1.57083 0.783544 1.56012</pose>
          <velocity>0.000528 -2.4e-05 0.003158 0.000232 0.006785 0.001406</velocity>
          <acceleration>-3.28599 -0.121078 7.43518 0.40391 -1.30422 -2.26497</acceleration>
          <wrench>-1.643 -0.060539 3.71759 0 -0 0</wrench>
        </link>
        <link name='sol_arka_teker'>
          <pose>0.130207 -0.072245 0.077499 1.57084 -0.800667 1.56011</pose>
          <velocity>0.000543 -4.9e-05 -0.003128 0.000266 0.007126 -0.001429</velocity>
          <acceleration>-3.44962 -0.13841 -7.42928 0.479006 -0.558671 2.46032</acceleration>
          <wrench>-1.72481 -0.069205 -3.71464 0 -0 0</wrench>
        </link>
        <link name='sol_on_teker'>
          <pose>0.135006 0.37773 0.077498 1.57084 0.781543 1.56015</pose>
          <velocity>0.000527 -1.6e-05 -0.003134 -2e-06 0.006818 0.001382</velocity>
          <acceleration>-3.3058 0.220101 -7.39204 -0.053204 -1.18813 -2.32595</acceleration>
          <wrench>-1.6529 0.11005 -3.69602 0 -0 0</wrench>
        </link>
      </model>
      <light name='sun'>
        <pose>0 0 10 0 -0 0</pose>
      </light>
    </state>
    <gui fullscreen='0'>
      <camera name='user_camera'>
        <pose>2.82396 -6.00509 33.6433 -0 1.47564 1.47219</pose>
        <view_controller>orbit</view_controller>
        <projection_type>perspective</projection_type>
      </camera>
    </gui>
  </world>
</sdf>
